Workbook

Sheet Finl Stmts
A1: The Boston Beer Company Inc Balance Sheet As of December 31 2023 | I1: The Boston Beer Company Inc Comparative Balance Sheet As of December 31 2023 | L1: The Boston Beer Company Inc Common Sized Balance Sheet As of December 31 2023 | P1: Boston Beer Company Inc Trend Analysis Balance Sheet (% of Base yr ) As of December 31 2023
B4: 2023 | D4: =B4-1 -> 2022 | F4: =D4-1 -> 2021 | I4: =B4 -> 2023 | J4: =D4 -> 2022 | L4: =B4 -> 2023 | M4: =D4 -> 2022 | N4: =F4 -> 2021 | P4: =B4 -> 2023
A5: Current Assets: | F5: Base Year
A6: Cash & Cash Equivalents (= Stmt of CF ending Cash Balance) | B6: 298491 | D6: 180560 | F6: 26853 | I6: =(B6-D6)/D6 -> 0.65314023 | J6: =(D6-F6)/F6 -> 5.7240159 | L6: =B6/$B$20 -> 0.20873599 | M6: =D6/$D$20 -> 0.12708575 | N6: =F6/$F$20 -> 0.019363506 | P6: =(B6-$F6)/$F6 -> 10.115741
A7: Marketable Securities / Investments/ Restricted Cash | F7: 39468 | I7: =IFERROR((B7-D7)/D7,0) -> 0 | J7: =(D7-F7)/F7 -> -1 | L7: =B7/$B$20 -> 0 | M7: =D7/$D$20 -> 0 | N7: =F7/$F$20 -> 0.028460092 | P7: =(B7-$F7)/$F7 -> -1
A8: Accounts Receivable, net | B8: 66997 | D8: 56672 | F8: 55022 | I8: =(B8-D8)/D8 -> 0.18218874 | J8: =(D8-F8)/F8 -> 0.029988005 | L8: =B8/$B$20 -> 0.046851278 | M8: =D8/$D$20 -> 0.039888145 | N8: =F8/$F$20 -> 0.03967597 | P8: =(B8-$F8)/$F8 -> 0.21764022
A9: Inventories | B9: 115773 | D9: 148450 | F9: 149118 | I9: =(B9-D9)/D9 -> -0.22012125 | J9: =(D9-F9)/F9 -> -0.0044796738 | L9: =B9/$B$20 -> 0.080960536 | M9: =D9/$D$20 -> 0.10448538 | N9: =F9/$F$20 -> 0.10752792 | P9: =(B9-$F9)/$F9 -> -0.22361486
A10: Prepaid expenses & Other Current Assest & Deferred Income Taxes Receivable | B10: =20538+1711 -> 22249 | D10: =27461+10126 -> 37587 | F10: =21462+53418 -> 74880 | I10: =(B10-D10)/D10 -> -0.40806662 | J10: =(D10-F10)/F10 -> -0.49803686 | L10: =B10/$B$20 -> 0.015558817 | M10: =D10/D20 -> 0.026455317 | N10: =F10/F20 -> 0.053995431 | P10: =(B10-$F10)/$F10 -> -0.70287126 | R10: Do not analyze this account
A11: Total current assets | B11: =SUM(B6:B10) -> 503510 | D11: =SUM(D6:D10) -> 423269 | F11: =SUM(F6:F10) -> 345341 | I11: =(B11-D11)/D11 -> 0.18957448 | J11: =(D11-F11)/F11 -> 0.22565522 | L11: =B11/$B$20 -> 0.35210662 | M11: =D11/$D$20 -> 0.29791459 | N11: =F11/$F$20 -> 0.24902292 | P11: =(B11-$F11)/$F11 -> 0.45800817
A12: Non-Current Assets:
A13: Net Property, Plant & Equipment ( Fixed Assets) | B13: 642509 | D13: 667909 | F13: 664815 | I13: =(B13-D13)/D13 -> -0.038029133 | J13: =(D13-F13)/F13 -> 0.0046539263 | L13: =B13/$B$20 -> 0.44930919 | M13: =D13/$D$20 -> 0.47010254 | N13: =F13/$F$20 -> 0.47939333 | P13: =(B13-$F13)/$F13 -> -0.033552191
A14: Operating Right-of-use Assests | B14: 35559 | D14: 43768 | F14: 52774 | I14: =(B14-D14)/D14 -> -0.18755712 | J14: =(D14-F14)/F14 -> -0.17065222 | L14: =B14/$B$20 -> 0.024866555 | M14: =D14/$D$20 -> 0.030805766 | N14: =F14/$F$20 -> 0.038054953 | P14: =(B14-$F14)/$F14 -> -0.3262023
A15: Goodwill | B15: 112529 | D15: 112529 | F15: 112529 | I15: =(B15-D15)/D15 -> 0 | J15: =(D15-F15)/F15 -> 0 | L15: =B15/$B$20 -> 0.078691994 | M15: =D15/$D$20 -> 0.079202659 | N15: =F15/$F$20 -> 0.081143855 | P15: =(B15-$F15)/$F15 -> 0
A16: Marketable Securities/Investments (long-term) | B16: 0 | D16: 0 | F16: 0 | I16: =IFERROR((B16-D16)/D16,0) -> 0 | J16: =IFERROR((D16-F16)/F16,0) -> 0 | L16: =B16/B20 -> 0 | M16: =D16/$D$20 -> 0 | N16: =F16/$F$20 -> 0 | P16: =IFERROR((B16-$F16)/$F16,0) -> 0
A17: Other intangibles | B17: 59644 | D17: 76324 | F17: 103677 | I17: =(B17-D17)/D17 -> -0.21854201 | J17: =(D17-F17)/F17 -> -0.26382901 | L17: =B17/B20 -> 0.041709295 | M17: =D17/$D$20 -> 0.053720052 | N17: =F17/$F$20 -> 0.074760741 | P17: =(B17-$F17)/$F17 -> -0.42471329
A18: Third-party production prepayments | B18: 33581 | D18: 61339 | F18: 88294 | I18: =(B18-D18)/D18 -> -0.45253428 | J18: =(D18-F18)/F18 -> -0.30528688 | L18: =B18/B20 -> 0.023483332 | M18: =D18/$D$20 -> 0.043172977 | N18: =F18/$F$20 -> 0.06366817 | P18: =(B18-$F18)/$F18 -> -0.61966838 | R18: Do not analyze this account
A19: Other Long Term Assets | B19: 42661 | D19: 35635 | F19: 19354 | I19: =(B19-D19)/D19 -> 0.19716571 | J19: =(D19-F19)/F19 -> 0.84122145 | L19: =B19/$B$20 -> 0.029833013 | M19: =D19/$D$20 -> 0.025081417 | N19: =F19/$F$20 -> 0.013956031 | P19: =(B19-$F19)/$F19 -> 1.2042472
A20: TOTAL ASSETS | B20: =SUM(B11:B19) -> 1429993 | D20: =SUM(D11:D19) -> 1420773 | F20: =SUM(F11:F19) -> 1386784 | I20: =(B20-D20)/D20 -> 0.0064894251 | J20: =(D20-F20)/F20 -> 0.024509224 | L20: =SUM(L11:L19) -> 1 | M20: =SUM(M11:M19) -> 1 | N20: =SUM(N11:N19) -> 1 | P20: =(B20-$F20)/$F20 -> 0.0311577
L21: should = 100% | M21: should = 100% | N21: should = 100%
A22: Current Liabilities:
A23: Accounts Payable | B23: 87245 | D23: 84248 | F23: 85920 | I23: =(B23-D23)/D23 -> 0.035573545 | J23: =(D23-F23)/F23 -> -0.019459963 | L23: =B23/$B$20 -> 0.061010788 | M23: =D23/$D$20 -> 0.059297298 | N23: =F23/$F$20 -> 0.061956296 | P23: =(B23-$F23)/$F23 -> 0.015421322
A24: Accrued liabilities | B24: 126930 | D24: 111153 | F24: 161552 | I24: =(B24-D24)/D24 -> 0.14193949 | J24: =(D24-F24)/F24 -> -0.31196766 | L24: =B24/$B$20 -> 0.088762672 | M24: =D24/$D$20 -> 0.078234173 | N24: =F24/$F$20 -> 0.11649399 | P24: =(B24-$F24)/$F24 -> -0.21430871
A25: Deferred Revenue (Unearned revenue) | I25: =(B25-D25)/D25 -> #DIV/0! | J25: =(D25-F25)/F25 -> #DIV/0! | L25: =B25/$B$20 -> 0 | M25: =D25/$D$20 -> 0 | N25: =F25/$F$20 -> 0 | P25: =(B25-$F25)/$F25 -> #DIV/0!
A26: Deferred Income Taxes | I26: =(B26-D26)/D26 -> #DIV/0! | J26: =(D26-F26)/F26 -> #DIV/0! | L26: =B26/$B$20 -> 0 | M26: =D26/$D$20 -> 0 | N26: =F26/$F$20 -> 0 | P26: =(B26-$F26)/$F26 -> #DIV/0! | R26: Do not analyze this account
A27: Other liabilities | I27: =(B27-D27)/D27 -> #DIV/0! | J27: =(D27-F27)/F27 -> #DIV/0! | L27: =B27/$B$20 -> 0 | M27: =D27/$D$20 -> 0 | N27: =F27/$F$20 -> 0 | P27: =(B27-$F27)/$F27 -> #DIV/0!
A28: Current portion of Long Term debt (interest bearing debt) + Leases | B28: 9113 | D28: 8866 | F28: 7634 | I28: =(B28-D28)/D28 -> 0.027859238 | J28: =(D28-F28)/F28 -> 0.16138329 | L28: =B28/$B$20 -> 0.0063727585 | M28: =D28/$D$20 -> 0.006240265 | N28: =F28/$F$20 -> 0.0055048227 | P28: =(B28-$F28)/$F28 -> 0.19373854
A29: Total current liabilities | B29: =SUM(B22:B28) -> 223288 | D29: =SUM(D22:D28) -> 204267 | F29: =SUM(F22:F28) -> 255106 | I29: =(B29-D29)/D29 -> 0.093118321 | J29: =(D29-F29)/F29 -> -0.19928579 | L29: =B29/$B$20 -> 0.15614622 | M29: =D29/$D$20 -> 0.14377174 | N29: =F29/$F$20 -> 0.18395511 | P29: =(B29-$F29)/$F29 -> -0.12472462
A30: Deferred Income Taxes - LT | B30: 85721 | D30: 96592 | F30: 87495 | I30: =(B30-D30)/D30 -> -0.11254555 | J30: =(D30-F30)/F30 -> 0.10397166 | L30: =B30/$B$20 -> 0.059945049 | M30: =D30/$D$20 -> 0.067985526 | N30: =F30/$F$20 -> 0.063092017 | P30: =(B30-$F30)/$F30 -> -0.020275444 | R30: Do not analyze this account
A31: Deferred Revenue (Unearned revenue) | I31: =(B31-D31)/D31 -> #DIV/0! | J31: =(D31-F31)/F31 -> #DIV/0! | L31: =B31/$B$20 -> 0 | M31: =D31/$D$20 -> 0 | N31: =F31/$F$20 -> 0 | P31: =(B31-$F31)/$F31 -> #DIV/0!
A32: Other Liabilities | B32: 6894 | D32: 6091 | F32: 6925 | I32: =(B32-D32)/D32 -> 0.13183385 | J32: =(D32-F32)/F32 -> -0.12043321 | L32: =B32/$B$20 -> 0.0048210026 | M32: =D32/$D$20 -> 0.0042871029 | N32: =F32/$F$20 -> 0.0049935679 | P32: =(B32-$F32)/$F32 -> -0.0044765343
A33: Long term debt (Interest bearing debt)+Leases | B33: 36161 | D33: 45274 | F33: 53849 | I33: =(B33-D33)/D33 -> -0.20128551 | J33: =(D33-F33)/F33 -> -0.15924158 | L33: =B33/$B$20 -> 0.025287536 | M33: =D33/$D$20 -> 0.031865752 | N33: =F33/$F$20 -> 0.038830128 | P33: =(B33-$F33)/$F33 -> -0.32847407
A34: Total Liabilities | B34: =SUM(B29:B33) -> 352064 | D34: =SUM(D29:D33) -> 352224 | F34: =SUM(F29:F33) -> 403375 | I34: =(B34-D34)/D34 -> -0.00045425638 | J34: =(D34-F34)/F34 -> -0.12680756 | L34: =B34/$B$20 -> 0.24619981 | M34: =D34/$D$20 -> 0.24791012 | N34: =F34/$F$20 -> 0.29087082 | P34: =(B34-$F34)/$F34 -> -0.12720421
A35: Other Equity:
A36: Non Controlling Interest (most companies do not have) | I36: =IFERROR((B36-D36)/D36,0) -> 0 | J36: =IFERROR((D36-F36)/F36,0) -> 0 | L36: =B36/$B$20 -> 0 | M36: =D36/$D$20 -> 0 | N36: =F36/$F$20 -> 0 | P36: =(B36-$F36)/$F36 -> #DIV/0!
A37: Preferred Stock (most companies do not have) | I37: =IFERROR((B37-D37)/D37,0) -> 0 | J37: =IFERROR((D37-F37)/F37,0) -> 0 | L37: =B37/$B$20 -> 0 | M37: =D37/$D$20 -> 0 | N37: =F37/$F$20 -> 0 | P37: =(B37-$F37)/$F37 -> #DIV/0!
A38: Common Equity:
A39: Common Stock, Class A and Class B | B39: =100+21 -> 121 | D39: =102+21 -> 123 | F39: =102+21 -> 123 | I39: =(B39-D39)/D39 -> -0.016260163 | J39: =(D39-F39)/F39 -> 0 | L39: =B39/$B$20 -> 8.4615799e-05 | M39: =D39/$D$20 -> 8.6572591e-05 | N39: =F39/$F$20 -> 8.8694418e-05 | P39: =(B39-$F39)/$F39 -> -0.016260163
A40: Additional Paid in Capital (APIC) | B40: 656297 | D40: 629515 | F40: 611622 | I40: =(B40-D40)/D40 -> 0.042543863 | J40: =(D40-F40)/F40 -> 0.029254997 | L40: =B40/$B$20 -> 0.4589512 | M40: =D40/$D$20 -> 0.44307923 | N40: =F40/$F$20 -> 0.44103624 | P40: =(B40-$F40)/$F40 -> 0.073043481
A41: Treasury Stock (a negative number) | I41: =(B41-D41)/D41 -> #DIV/0! | J41: =(D41-F41)/F41 -> #DIV/0! | L41: =B41/$B$20 -> 0 | M41: =D41/$D$20 -> 0 | N41: =F41/$F$20 -> 0 | P41: =(B41-$F41)/$F41 -> #DIV/0!
A42: Retained Earnings | B42: 421568 | D42: 439121 | F42: 371858 | I42: =(B42-D42)/D42 -> -0.039973037 | J42: =(D42-F42)/F42 -> 0.18088356 | L42: =B42/$B$20 -> 0.29480424 | M42: =D42/$D$20 -> 0.30907189 | N42: =F42/$F$20 -> 0.26814414 | P42: =(B42-$F42)/$F42 -> 0.13368006
...

Sheet Ratios
A1: Company Name | B1: Boston Beer Company Inc | H1: Is the Ratio Trend "Favorable","Unfavorable" or "Stable"? | I1: Is the ratio itself "Favorable" or "Unfavorable"? | J1: Interpretation/Implications of each ratio
A2: Student Name | B2: Laura Dampman
A3: Ratio Analysis | B3: ='Finl Stmts'!B4 -> 2023 | D3: ='Finl Stmts'!D4 -> 2022 | F3: ='Finl Stmts'!F4 -> 2021
A4: Liquidity Ratios: any Going Concern issues? Can the firm stay in business in the short term? Should lenders extend credit to this firm?
A5: Current Ratio: measures ability to pay short term debt, but has problem with inventory value and quality of A/R | H5: Trend favorable | I5: In 2021 unfavorable and for 2022 to 2023 favorable | J5: Boston Beer Company's quick ratio showed a favorable trend overall, with the ratio improving each year reflecting improved liquidity. However, in 2021, the ratio itself was unfavorable, indicating liquidity challenges. With total current assets of $345,341 and total current liabilities of $255,106, the company may have struggled to meet short-term obligations. Which is reflected in the funding gap and low operating cash flows for 2021. The company's ratio saw significant improvement in 2022, reflecting better short term financial stability and is reflected in the large increase in cash and cash equivalents in 2022 on the balance sheet. In 2023, the ratio improved but at a much slower pace compared to 2022. This is concerning because while the company is improving their liquidity, the concern is that excess liquidity is not being invested for future growth which is supported by the company's negative investing cash flows from both 2022 and 2023.
A6: Current assets | B6: ='Finl Stmts'!B11 -> 503510 | C6: =B6/B7 -> 2.2549801 | D6: ='Finl Stmts'!D11 -> 423269 | E6: =D6/D7 -> 2.072136 | F6: ='Finl Stmts'!F11 -> 345341 | G6: =F6/F7 -> 1.3537157
A7: Current liabilities | B7: ='Finl Stmts'!B29 -> 223288 | D7: ='Finl Stmts'!D29 -> 204267 | F7: ='Finl Stmts'!F29 -> 255106
A9: Quick Ratio: measures ability to easily pay short term debt & avoids problem of inventory value, but still has A/R quality issue | H9: Trend favorable | I9: In 2021 unfavorable and for 2022 to 2023 favorable | J9: Boston Beer Company’s quick ratio showed a favorable trend overall, improving from 0.5 in 2021 to 1.2 in 2022 and 1.6 in 2023, indicating a stronger liquidity position each year. In 2021, the company faced liquidity struggles, with low cash and receivables relative to its liabilities and no reliance on external financing. By 2022, liquidity improved as operating cash flows strengthened, providing better short-term financial stability. In 2023, the quick ratio increased further, suggesting strong financial health, though excess liquidity raises concerns about inefficient reinvestment. Despite improving liquidity, declining sales across all three years indicate that these improvements were driven more by asset management and cost control rather than revenue growth.
A10: Cash + marketable securities + Net A/R | B10: ='Finl Stmts'!B6+'Finl Stmts'!B7+'Finl Stmts'!B8 -> 365488 | C10: =B10/B11 -> 1.6368457 | D10: ='Finl Stmts'!D6+'Finl Stmts'!D7+'Finl Stmts'!D8 -> 237232 | E10: =D10/D11 -> 1.1613819 | F10: ='Finl Stmts'!F6+'Finl Stmts'!F7+'Finl Stmts'!F8 -> 121343 | G10: =F10/F11 -> 0.47565718
A11: Current liabilities | B11: ='Finl Stmts'!B29 -> 223288 | D11: ='Finl Stmts'!D29 -> 204267 | F11: ='Finl Stmts'!F29 -> 255106
A13: Cash Ratio: conservative variation of Quick Ratio: no A/R quality issue & no inventory valuation issue | H13: Favorable trend | I13: In 2021 unfavorable, for 2022 moderate to stable and in 2023 favorable | J13: Boston Beer Company's cash ratio has shown an overall favorable trend, indicating improved liquidity and a reduced risk of short-term financial distress. In 2021, the company’s cash ratio was unfavorable, signaling that it did not have enough cash to fully cover its current liabilities. By 2022, liquidity had improved, though the ratio remained below the favorable threshold at 88%. In 2023, the ratio moved into the favorable range, suggesting that the company could comfortably meet its short-term liabilities. However, a cash ratio that is too high may also indicate inefficiency, as excess cash sitting idle is not being reinvested to generate returns or support future growth.
A14: Cash + Marketable Securities | B14: ='Finl Stmts'!B6+'Finl Stmts'!B7 -> 298491 | C14: =B14/B15 -> 1.3367982 | D14: ='Finl Stmts'!D6+'Finl Stmts'!D7 -> 180560 | E14: =D14/D15 -> 0.88394112 | F14: ='Finl Stmts'!F6+'Finl Stmts'!F7 -> 66321 | G14: =F14/F15 -> 0.25997429
A15: Current liabilities | B15: ='Finl Stmts'!B29 -> 223288 | D15: ='Finl Stmts'!D29 -> 204267 | F15: ='Finl Stmts'!F29 -> 255106
A17: Sustainable cash flow: Cash available to pay investors And invest extra for higher future growth rates in sales | J17: The trend in Boston Beer Company's sustainable cash flow is favorable, as the company has improved its ability to generate cash available for investors and reinvestment over the past three years. Sustainable cash flow increased significantly from a negative value in 2021,an unfavorable position, to a positive value in 2022, then nearly doubled in 2023. However, while the cash flow trend appears positive, it is crucial to recognize that Boston Beer Company's operational cash flow is not driven by strong core business performance, as sales have declined. If core sales continue to fall, this improvement may not be sustainable in the long term. Instead, the company may simply be temporarily covering deeper financial issues, much like placing a bandage over a widening gap.
A18: Cash flow from operations (Stmt of CF) - Capital expenditures (Tangible & Intangible asset purchases) | B18: ='Finl Stmts'!B114+'Finl Stmts'!B118+'Finl Stmts'!B122 -> 201064 | D18: ='Finl Stmts'!D114+'Finl Stmts'!D118+'Finl Stmts'!D122 -> 109363 | F18: ='Finl Stmts'!F114+'Finl Stmts'!F118+'Finl Stmts'!F122 -> -91622 | H18: Trend favorable | I18: In 2021 unfavorable and for 2022 to 2023 favorable
A20: Cash flow ratio: Ability of cash flow from operations to pay obligations as they become due. | H20: Trend favorable | I20: In 2021 unfavorable, in 2022 moderate to stable and in 2023 favorable | J20: Boston Beer Company's cash flow ratio has shown an overall favorable trend, steadily improving over the past three years. In 2021, the ratio, 0, was unfavorable and considered high risk, as the company did not generate enough operational cash flow to cover its short-term liabilities, relying instead on debt sales to meet its obligations. By 2022, the ratio improved to 1, with operational cash flow improving, though it still fell short of fully covering short-term liabilities. In 2023, the company finally had enough cash flow from operations to fully cover their short term debt while still having some excess cash remaining. This progression indicates that Boston Beer Company moved from financial strain to stability and now enjoys strong liquidity, which would typically position a company well for future growth and investment. However, a key concern is that much of the company’s operational cash flow over this period came from the liquidation of inventory and debt sales, rather than increased sales revenue. Since overall sales declined, relying on internal asset sales and debt to generate cash is unsustainable in the long run, as there is only so much a company can liquidate before depleting its resources.
A21: Cash flow from operations (Stmt of CF) | B21: ='Finl Stmts'!B114 -> 265151 | C21: =B21/B22 -> 1.1874843 | D21: ='Finl Stmts'!D114 -> 199945 | E21: =D21/D22 -> 0.97884142 | F21: ='Finl Stmts'!F114 -> 56297 | G21: =F21/F22 -> 0.22068082
A22: Current liabilities | B22: ='Finl Stmts'!B29 -> 223288 | D22: ='Finl Stmts'!D29 -> 204267 | F22: ='Finl Stmts'!F29 -> 255106
A24: Asset Management /Activity Ratios
B25: =B3 -> 2023 | D25: =D3 -> 2022 | F25: =F3 -> 2021
A26: Inventory turnover ratio: # times sell and replace inventory during the year | H26: Trend is stable | I26: In 2021 favorable, in 2022 unfavorable and 2023 favorable agian | J26: Boston Beer Company's inventory turnover ratio is slightly favorable/stable. In 2021, with a ratio of 8.4, it shows that company sold and replaced inventory at a reasonable pace. In 2022 the company's ratio, at 8.4, indicates a slight decrease in turnover suggesting that inventory was moving more slowly. This could have led to potentially higher costs or excess stock, indicating inefficiencies in demand and inability to sell inventory quick enough. Which most certainly put pressure on Boston Beer Company's cash flow. In 2023 the increase in turnover suggest improved inventory efficiency. However with inventory dropping by -22% and sales declining during the same time period, this would indicate that the improvement was not due to higher demand but rather cost cutting measures or liquidation. This poses sustainability risks if demand doesn’t rebound and sales increase.
A27: Cost of Goods Sold | B27: ='Finl Stmts'!B69 -> 1156256 | C27: =B27/B28 -> 8.7521223 | D27: ='Finl Stmts'!D69 -> 1228348 | E27: =D27/D28 -> 8.2559146 | F27: ='Finl Stmts'!F69 -> 1259830 | G27: =F27/F28 -> 8.4485441
A28: Average Inventory | B28: =('Finl Stmts'!B9+'Finl Stmts'!D9)/2 -> 132111.5 | D28: =('Finl Stmts'!D9+'Finl Stmts'!F9)/2 -> 148784 | F28: =('Finl Stmts'!F9) -> 149118
A30: Days in Inventory / Inventory Conversion Period: The average time required to convert raw materials into finished goods (or to purchase products) and then to sell them. | J30: Boston Beer Company's inventory conversion period in 2021 was favorable at 43 days, indicating the company was efficiently managing its inventory with a good balance between supply and demand, reducing the risk of excess stock. In 2022, the ratio showed that inventory turnover remained steady, with a slight increase to 44 days, which is somewhat concerning but still suggests continued efficiency. In 2023, the ratio remained favorable as the days in inventory decreased to 42 days, indicating that products were moving more quickly. While this would typically suggest strong product demand, the company's declining sales in 2023 suggest otherwise. Instead, the decrease in days in inventory likely indicates that Boston Beer Company was liquidating its inventory or offering discounts to clear excess stock.
A31: 365 | B31: =365 -> 365 | C31: =B31/B32 -> 41.704171 | D31: =365 -> 365 | E31: =D31/D32 -> 44.210729 | F31: =365 -> 365 | G31: =F31/F32 -> 43.20271
A32: Inventory Turnover Ratio | B32: =C27 -> 8.7521223 | D32: =E27 -> 8.2559146 | F32: =G27 -> 8.4485441 | H32: Trend is favorable | I32: Favorable in 2021,2022 and 2023
A34: Days Sales Outstanding (DSO) / Receivables Collection Period: The average time to collect cash from credit sales | J34: Boston Beer Company's receivables collection period ratios shows an unfavorable trend with 2021 and 2022's ratio remaining favorable at 10 but then 2023's ratio increasing to 12 which is still efficient but concerning that it is growing. In 2021 and 2022 the company collected payments from customers quickly, well within its 30 day credit policy. In 2023 the ratio slightly grew to 12 but is still far below the company's 30 day credit policy. However the rising trend could indicate slower payments which warrant closer monitoring to prevent future cash flow issues.
A35: Net Receivables | B35: ='Finl Stmts'!B8 -> 66997 | C35: =B35/B36 -> 12.17445 | D35: ='Finl Stmts'!D8 -> 56672 | E35: =D35/D36 -> 9.8956817 | F35: ='Finl Stmts'!F8 -> 55022 | G35: =F35/F36 -> 9.7603107 | H35: Trend is unfavorable | I35: In 2021 favorable, 2022 favorable and 2023 unfavorable
A36: Avg Credit Sales per day (Annual credit sales/365) | B36: ='Finl Stmts'!B68/365 -> 5503.0822 | D36: ='Finl Stmts'!D68/365 -> 5726.9425 | F36: ='Finl Stmts'!F68/365 -> 5637.3205
A37: Note: Assume the company credit policy is 30 days
A39: Payables turnover (in days)/Payables Deferral Period: Average time between the purchase of materials, labor & products & payment of cash for them | J39: Boston Beer Company's payable turnover ratio is overall unfavorable with the days to pay suppliers increasing over time. The ratio for the years 2021 and 2022 were stable, taking the company about 15 days to pay suppliers which is a reasonable time frame. Since 2021 and 2022 ratios are stable, this suggests consistent payment practices for those years. In 2023, there was an increase in the payment period suggesting the company is taking slightly longer to pay its suppliers. This is further confirmed with the company's balance sheet, showing an increase in the accounts payable amount for 2023. Delaying payments to suppliers could be a strategic move on the company's part to conserve cash, however if this trend were to continue it would strain future supplier relationships.
A40: 365 | B40: 365 | C40: =B40/B41 -> 27.067944 | D40: 365 | E40: =D40/D41 -> 25.282461 | F40: 365 | G40: =F40/F41 -> 24.892882 | H40: Trend is unfavorable | I40: In 2021 and 2022 stable and for 2023 unfavorable
A41: Cost of Goods Sold/Avg accounts payable | B41: ='Finl Stmts'!B69/(('Finl Stmts'!B23+'Finl Stmts'!D23)/2) -> 13.484585 | D41: ='Finl Stmts'!D69/(('Finl Stmts'!D23+'Finl Stmts'!F23)/2) -> 14.436886 | F41: ='Finl Stmts'!F69/'Finl Stmts'!F23 -> 14.662826
A42: Note: Assume the supplier’s credit policy is 30 days
A44: Operating Cycle (days): Average time to conduct the business cycle: from initial purchase of materials/products to collect cash from sales | J44: Overall the ratio trend for Boston Beer Company's operating cycle is stable. In 2021 the operating cycle was 53 days, meaning the company was marginally more efficient in turning its investments in inventory and receivables into cash. In 2022 and 2023 the company slightly increased their operating cycle to 54 days which still indicates consistency in the company's ability to convert inventory and receivables into cash. The slight increase in later years is concerning because if the trend were to continue this would raise concerns about the company's operational efficiency.
A45: Inventory Conversion Period + Receivables Collection Period | C45: =C31+C35 -> 53.878621 | E45: =E31+E35 -> 54.10641 | G45: =G31+G35 -> 52.963021 | H45: Trend is stable | I45: In 2021, 2022 and 2023 stable
A47: Cash Cycle (days): The average length of time cash is tied up in working capital: need to get a bank loan or have excess cash on hand to sustain business during this time | J47: Boston Beer Company's cash cycle ratio is overall favorable. In 2021 the cash cycle was 28 days and this suggests a relatively stable cash flow process. In 2022 the cash cycle of 29 days shows that the company took a slightly longer time to convert investments in working capital back into cash. This may indicate a temporary slowdown in cash turnover. In 2023, the cash cycle was 27 days, indicating that cash was tied up in working capital for a slightly shorter period compared to 2022 and 2021. This shows improved liquidity and cash flow management.
A48: Gross operating cycle - Payables deferral period (in days) | C48: =C45-C40 -> 26.810677 | E48: =E45-E40 -> 28.82395 | G48: =G45-G40 -> 28.070138 | H48: Trend is favorable | I48: In 2021 favorable, 2022 favorable and 2023 slightly unfavorable
A50: Fixed Asset Turnover Ratio : $$ of Sales generated by $1 of Fixed Assets: how efficiently are you using your Fixed Assets? | J50: Over all the fixed asset turnover ratio for Boston Beer Company was slightly unfavorable to stable. In 2023, the fixed asset turnover ratio was 3.07 indicating a slight decline in efficiency compared to 2022. This suggests that the company generated slightly less revenue per dollar of fixed assets due to decreased sales. In 2022, the ratio increased to 3.14, showing a slight improvement in asset utilization compared to 2021. This suggest the company was able to generate more revenue per dollar of fixed assets, reflecting better operational efficiency. In 2021, with at ratio of 3.10, the company had a solid level of asset utilization. Though it is slightly lower than 2022, it was relatively stable.
A51: Sales | B51: ='Finl Stmts'!B68 -> 2008625 | C51: =B51/B52 -> 3.0656249 | D51: ='Finl Stmts'!D68 -> 2090334 | E51: =D51/D52 -> 3.1369346 | F51: ='Finl Stmts'!F68 -> 2057622 | G51: =F51/F52 -> 3.0950294 | H51: Trend is slightly unfavorabe/stable | I51: In 2021 unfavorable, 2022 favorable and in 2023 unfavorable
...

Sheet Add'l Calc
B2: Boston Beer Company
B3: Laura Dampman
A4: Phase I: Additional Calculations & Analysis
B5: See Step 8 Instructions for Questions to Answer | I5: Analysis: Trend? What does it indicate?
A6: Step 8: | C6: ='Finl Stmts'!B4 -> 2023 | E6: ='Finl Stmts'!D4 -> 2022 | G6: ='Finl Stmts'!F4 -> 2021
C7: Popular measure of Free Cash Flow from operations before considering impacts of debt, taxes and future growth needs.
A8: a1 | B8: EBITDA: (EBIT + Depreciation + Amortization) is a quick and dirty measure of cash generated by operations | C8: ='Finl Stmts'!B77+'Finl Stmts'!B95 -> 188142 | E8: ='Finl Stmts'!D77+'Finl Stmts'!D95 -> 172147 | G8: ='Finl Stmts'!F77+'Finl Stmts'!F95 -> 80093 | I8: EBITDA Growth is a positive indicator of operational profitability, but it's crucial to recognize that the extraordinary growth in 2022 might have been driven by one-time gains or cost cuts rather than ongoing improvements in core operations. The slower growth in 2023, combined with declining revenues and increasing liabilities, suggests that this growth might not be sustainable. With operational cash flows not being able to cover current liabilities in 2021 and 2022 could signal potential financial stress that could hinder long term stability.
A10: b | B10: NOPAT: (EBIT*(1-T)). Use T from tax analysis below | C10: ='Finl Stmts'!B77*C19 -> 74000.74 | E10: ='Finl Stmts'!D77*E19 -> 67185.34 | G10: ='Finl Stmts'!F77*G19 -> 5917.78 | I10: NOPAT shows that after-tax operating performance is improving, but again, the sharp increase in 2022 could have been driven by temporary factors like tax benefits or non-operating gains. The declining operational metrics, such as decreased sales and impairments, point to potential weaknesses in maintaining these profit levels.
I11: The increase in working capital from 2021 to 2023 suggests that Boston Beer Company is strengthening its liquidity position, which is generally a positive sign for its ability to meet short-term obligations and finance day-to-day operations. However, the significant growth in working capital, especially in 2022, raises questions about the efficiency of how current assets are being managed, particularly in areas like accounts receivable and inventory. If the increase in working capital is largely driven by uncollected receivables or unsold inventory, it could signal potential operational inefficiencies that need to be addressed. While the overall trend is positive, it will be important for the company to ensure that these increased reserves are being used effectively to drive growth and profitability rather than simply accumulating without turning it into profitable returns.
A12: c 1. | B12: Working Capital (WC): = CA - CL | C12: ='Finl Stmts'!B11-'Finl Stmts'!B29 -> 280222 | E12: ='Finl Stmts'!D11-'Finl Stmts'!D29 -> 219002 | G12: ='Finl Stmts'!F11-'Finl Stmts'!F29 -> 90235
B13: Net Working Capital Ratio: (CA - CL) / Total Assets
A14: d | B14: Free Cash Flow (Modified): (NOPAT+ Depreciation & Amortization) - (CapEx) Note: if FCF is negative, then company needs to raise new money in capital markets to invest in CapX | C14: =C10+'Finl Stmts'!B95+'Finl Stmts'!B118 -> 98054.74 | E14: =E10+'Finl Stmts'!D95+'Finl Stmts'!D118 -> 57959.34 | G14: =G10+'Finl Stmts'!F95+'Finl Stmts'!F118 -> -69905.22 | I14: While the increase in free cash flow is a positive sign, the underlying factors—declining sales, growing accounts receivable, increasing accounts payable, and negative investing cash flows—indicate that the company may not be improving its operational efficiency. Instead, it appears to be generating cash through internal liquidity management (such as using working capital adjustments, reducing debt, and potentially cashing in short-term investments). This reliance on financial maneuvers to generate cash is not sustainable in the long term. If the company continues to see declining sales and operational inefficiencies (increased receivables), it could face liquidity challenges in the future. The company needs to focus on improving its core business operations and reducing reliance on these internal cash-generation strategies to ensure long-term financial health and sustainability.
B15: Note: Source of CapEx = Stmt of Cash flows Investing section: Purchases of Property & Equipment + Purchases of Intangible assets (do not include one time purchases of a business and do not include goodwill). Be careful because this is shown as a negative number. Watch the parenthesis. It should reduce NOPAT
A17: e | B17: Effective Tax Rate: Tax Expense/Earnings Before Taxes (EBT): (compute for each year) | C17: ='Finl Stmts'!B84/'Finl Stmts'!B83 -> 0.30421214 | E17: ='Finl Stmts'!D84/'Finl Stmts'!D83 -> 0.26437071 | G17: ='Finl Stmts'!F84/'Finl Stmts'!F83 -> -1.106383 | I17: Boston Beer Company's effective tax rate trend is unfavorable. It shows an increase in the effective tax rate from 2021 to 2023, from a negative tax rate in 2021 to a 30% rate in 2023. The only year that the effective tax rate did not come close to the effective tax rate was in 2021, with an effecitve tax rate of -111% which the sharp negative rate was likely driven by tax benefits from losses, impairments, or adjustments in deferred tax assets noted in financial statements. The trend from 2021 (a tax benefit) to 2023 (a higher-than-nominal tax rate) is unfavorable as it suggests that the company is facing higher tax expenses, which could reduce future profitability if the trend continues.
B18: Nominal Tax Rate (T) (statutory 21%+4% state + 1% local) | C18: =0.21+0.04+0.01 -> 0.26 | E18: =0.21+0.04+0.01 -> 0.26 | G18: =0.21+0.04+0.01 -> 0.26
B19: After Tax Impact (1-T) (what company keeps) | C19: =1-C18 -> 0.74 | E19: =1-E18 -> 0.74 | G19: =1-G18 -> 0.74
A21: f | B21: Sources of Funding for Total Assets: | C21: Book Value $$ | E21: % | I21: The 2023 reduction in free liabilities from operations is generally a favorable trend since it reflects a more balanced and sustainable approach. However, maintaining some level of operational liabilities is normal and can be beneficial for cash flow management. The company should ensure that further reductions do not harm operational efficiency or supplier relationships.
A22: 1) | B22: Vendor/Supplier/Govt/EE Funding: (Free liabilities from Operations) | C22: ='Finl Stmts'!B34-'Finl Stmts'!B33-'Finl Stmts'!B28 -> 306790 | E22: ='Finl Stmts'!D34-'Finl Stmts'!D33-'Finl Stmts'!D28 -> 298084 | G22: ='Finl Stmts'!F34-'Finl Stmts'!F33-'Finl Stmts'!F28 -> 341892
A24: 2) | B24: Debt Investor Funding: (Interest bearing): | C24: ='Finl Stmts'!B28+'Finl Stmts'!B33 -> 45274 | E24: ='Finl Stmts'!D28+'Finl Stmts'!D33 -> 54140 | G24: ='Finl Stmts'!F28+'Finl Stmts'!F33 -> 61483 | I24: The decrease in debt from 2021 to 2023 is a favorable trend as it suggests that Boston Beer Company is reducing financial risk and strengthening its balance sheet. However, maintaining a manageable level of debt can be beneficial for leveraging growth opportunities, so the company should ensure it has a balanced structure moving forward.
A26: 3) | B26: Equity Investor Funding: $$ + %:
B27: Common Equity | C27: ='Finl Stmts'!B44 -> 1077929 | E27: ='Finl Stmts'!D44 -> 1068549 | G27: ='Finl Stmts'!F44 -> 983409 | I27: The trend in equity investor funding is favorable as Boston Beer Company has consistently increased its equity base. This growth suggests financial resilience and strengthens the company's capital structure. Maintaining a high equity-to-assets ratio reduces financial risk and provides flexibility, reflecting a cautious approach to funding rather than relying heavily on external borrowing.
B28: Preferred Equity | C28: ='Finl Stmts'!B37 -> 0 | E28: ='Finl Stmts'!D37 -> 0 | G28: ='Finl Stmts'!F37 -> 0
B29: Noncontrolling Interest | C29: ='Finl Stmts'!B36 -> 0 | E29: ='Finl Stmts'!D36 -> 0 | G29: ='Finl Stmts'!F36 -> 0
B30: SubTotal Total Assets | C30: =SUM(C22:C29) -> 1429993 | E30: =SUM(E22:E29) -> 1420773 | G30: =SUM(G22:G29) -> 1386784
B31: Total Assets per Balance Sheet | C31: ='Finl Stmts'!B20 -> 1429993 | E31: ='Finl Stmts'!D20 -> 1420773 | G31: ='Finl Stmts'!F20 -> 1386784
B32: Difference (should = 0) | C32: =C30-C31 -> 0 | E32: =E30-E31 -> 0 | G32: =G30-G31 -> 0
A34: g | B34: All Interest Bearing Debt/ EBITDA. Minimum # years for company to pay off debt IF it paid no taxes, interest expense, pmts to shareholders or made investments. | C34: =C22/C8 -> 1.6306301 | E34: =E22/E8 -> 1.7315666 | I34: The 2-year Debt/EBITDA ratio in both 2023 and 2022 is a favorable trend, indicating the company is maintaining a strong ability to service its debt. This is a favorable trend.
A36: h | B36: What story is the data telling? List a MINIMUM of 2 things the company doing well . | C36: Areas that Boston Beer Company has done well in are effective cash generation and cost cutting measures, debt management, maintaining a stable share count and increasing EPS. Boston Beer Company has done well in implementing cost-cutting measures and generating cash through asset liquidation. By reducing operating expenses and strategically liquidating short-term assets, the company was able to increase net income despite declining sales. In 2022, Boston Beer Company's net income surged by 362%, and in 2023, it grew another 13%, largely due to cost-cutting efforts and asset sales. This also led to a 572% increase in cash and cash equivalents in 2022 and another 65% increase in 2023, further strengthening the company’s liquidity position. The company also paid down 13% of its long-term debt in 2022 and maintained that level in 2023, reducing financial risk. While cost-cutting and asset liquidation are not sustainable long-term solutions, it helped stabilize the company’s financials and provided flexibility for future reinvestment. Moving forward, Boston Beer must shift from cutting costs to driving revenue growth to sustain profitability. Boston Beer Company has also been able to maintain a stable share count and increasing EPS. Despite financial challenges, Boston Beer Company has kept the number of outstanding shares stable. This means that its earnings per share (EPS) growth was driven by actual net income growth rather than artificial stock buybacks. In 2022, net income grew by 362%, leading to a sharp increase in EPS and then the net income rose again in 2023 by 13%. This stability in share count benefits long-term investors because it ensures EPS growth is not artificially inflated by reducing the number of shares. However, to maintain investor confidence, Boston Beer must now focus on driving revenue growth rather than relying on cost-cutting or asset liquidations. While Boston Beer Company has taken steps to strengthen its balance sheet and ensure liquidity, the combination of declining sales, asset liquidation, and a lack of growth investments, that I will be mentioning in the next section, raises concerns about the company's long-term growth prospects. Boston Beer Company's conservative financial approach may mitigate short-term risks, but without revenue growth and operational improvements, the company could face stagnation or further financial pressure in the future.
B37: List a MINIMUM of 3 areas the company needs to improve to help their financial performance | C37: Boston Beer Company's financial statements reveal that they have taken a conservative financial approch to help mitigate short term risks. There are several concerning trends, highlighting areas where the company must improve to achieve sustainable financial growth. One critical area for improvement is marketable securities and short-term investments. In 2022, Boston Beer Company completely liquidated all of its marketable securities and investments, likely due to the need for an influx of cash. This decision followed two consecutive years (2021 and 2022) where operating cash flows were negative, meaning the company did not generate enough money from its core business to cover its current liabilities. The problem is that this trend continued into 2023, with marketable securities and investments still at 0%. By failing to reinvest cash into short-term securities, the company now lacks easily accessible liquid assets, which can make cash flow management more difficult. Additionally, Boston Beer is missing out on potential returns that it could have earned through interest or capital appreciation. Holding excess cash may seem like a prudent approach, but without reinvesting, it becomes an inefficient use of capital. Investors could interpret this as a lack of strategic planning or growth opportunities, which may negatively affect market confidence and the company’s ability to secure favorable financing in the future. To improve, Boston Beer Company should develop a balanced approach between maintaining liquidity and reinvesting cash into short-term securities or other high-return opportunities. Another major area of concern is fluctuating sales and weakening investor confidence. Boston Beer Company's sales grew by only 2% from 2021 to 2022 but then declined by 4% from 2022 to 2023. Despite an increasing EPS, the company’s stock price has been falling significantly, signaling investor concerns about future growth. The company's P/E ratio declined sharply from 426.21 in 2021 to 38.78 in 2023, suggesting investors initially overvalued the company but later adjusted their expectations as growth slowed. As well as the price-to-sales ratio decreasing each year, further indicating weak investor sentiment. Compounding this issue, Boston Beer Company did not pay dividends in any of the three years, despite a sharp increase in cash and cash equivalents (572% in 2022 and 65% in 2023). This suggests the company was holding onto cash instead of reinvesting or rewarding shareholders, making it less attractive to investors. While retaining cash can be a strategic move, Boston Beer has not used these funds effectively for reinvestment. Instead of relying on cost-cutting measures that artificially boost net income, the company should focus on increasing sales and operational efficiency to drive sustainable long-term profit growth. Additionally, the company’s negative financing cash flows in 2021 and 2023 indicate that it was paying off debt rather than securing new financing. While reducing debt can be a positive move, this strategy must be balanced with investments in future growth. The lack of both dividends and reinvestment efforts suggests that Boston Beer is failing to provide sufficient value to shareholders, which could lead to further stock price declines and reduced investor interest. In addition to declining sales, Boston Beer Company's accounts receivable (A/R) has increased significantly, rising by 3% in 2022 and then another 18% in 2023. Normally, A/R growth should align with rising sales, but Boston Beer’s sales actually declined in 2023. This mismatch suggests that the company is not efficiently collecting payments from customers, which could lead to future cash flow issues. One possible explanation is that Boston Beer loosened its credit terms to boost sales following weaker results in 2021. While this can be an effective short-term strategy, it carries risks like a higher A/R means more money is tied up in unpaid invoices, reducing available cash. Failure to collect payments on time increases the likelihood of bad debt, which can reduce net income and investors may see rising A/R as a warning sign that the company is struggling to manage its cash flow. To address this issue, Boston Beer Company should tighten its credit policies and improve collection efforts. This includes better monitoring of outstanding receivables, enforcing stricter payment deadlines, and evaluating customer creditworthiness more carefully. Without these changes, the company risks higher bad debt expenses and further financial instability.
